<mujoco model="tiny muscle">
  <include file="./common/skybox.xml"/>

  <option timestep="0.001" gravity="0 -9.81 0"/>
  <size njmax="50" nconmax="10" nstack="200"/>

  <visual>
    <rgba haze=".3 .3 .3 1"/>
  </visual>

  <asset>
    <texture name="texplane" type="2d" builtin="checker" rgb1=".25 .25 .25" rgb2=".3 .3 .3" width="512" height="512" mark="cross" markrgb=".8 .8 .8"/>
    <material name="matplane" reflectance="0.3" texture="texplane" texrepeat="1 1" texuniform="true"/>
  </asset>


  <default>
    <joint type="hinge" pos="0 0 0" axis="0 0 1" limited="true" range="-120 120" damping="0.02"/>
    <muscle ctrllimited="false" ctrlrange="0 1"/>
  </default>

  <worldbody>
    <geom name="floor" pos="0 0 -0.5" size="0 0 1" type="plane" material="matplane"/>
    <light directional="true" diffuse=".8 .8 .8" specular=".2 .2 .2" pos="0 0 5" dir="0 0 -1"/>

    <camera name="upfront" pos="1.288 0.006 1.717" xyaxes="-0.005 1.000 0.000 -0.865 -0.004 0.502"/>
    <camera name="upperleft" pos="0.792 -1.306 1.560" xyaxes="0.855 0.519 0.000 -0.417 0.687 0.595"/>


    <site name="s0" pos="-0.15 0 0" size="0.02"/>
    <site name="x0" pos="0 -0.15 0" size="0.02" rgba="0 .7 0 1" group="1"/>
    <site name="x1" pos="0 0.15 0" size="0.02" rgba="0 .7 0 1" group="1"/>

    <body pos="0 0 0" euler="0 0 0">
      <geom name="upper arm" type="capsule" size="0.045" fromto="0 0 0  0.5 0 0" rgba=".5 .1 .1 1" mass="0.5"/>
      <joint name="shoulder"/>
      <geom name="shoulder" type="cylinder" pos="0 0 0" size=".1 .05" rgba=".5 .1 .8 .5" mass="0" group="1"/>

      <site name="s1" pos="0.15 0.06 0" size="0.02"/>
      <site name="s2" pos="0.15 -0.06 0" size="0.02"/>

    </body>
  </worldbody>

  <tendon>
    <spatial name="SF" width="0.01">
      <site site="s0"/>
      <geom geom="shoulder" sidesite="x1"/>
      <site site="s1"/>
    </spatial>

    <spatial name="SE" width="0.01">
      <site site="s0"/>
      <geom geom="shoulder" sidesite="x0"/>
      <site site="s2"/>
    </spatial>

  </tendon>

  <actuator>
    <muscle name="SF" tendon="SF"/>
    <muscle name="SE" tendon="SE"/>
  </actuator>
</mujoco>
