<mujoco model="kinematic-chain">
  <include file="./common/skybox.xml"/>
  <include file="./common/visual.xml"/>
  <include file="./common/materials.xml"/>
  
  <option timestep="0.001" integrator="RK4">
    <flag contact="disable" gravity="disable" energy="enable"/>
  </option>
  
  <default>
    <default class="pole">
      <joint type="hinge" axis="0 1 0" stiffness="10" springref="0" damping="1e-1"/>
      <geom type="capsule" fromto="0 0 0 0 0 1" size="0.045" material="self" mass=".1"/>
    </default>
  </default>
  
  <worldbody>
    <light name="light" pos="0 0 36"/>
    
    <camera name="fixed" pos="0 -6 1" zaxis="0 -1 0"/>
    <camera name="lookatcart" mode="targetbody" target="cart" pos="0 -2 2"/>
    
    <geom name="floor" pos="0 0 -.25" size="100 100 .2" type="plane" material="grid"/>
    <geom name="rail1" type="capsule" pos="0  .07 2" zaxis="1 0 0" size="0.02 20" material="decoration" />
    <geom name="rail2" type="capsule" pos="0 -.07 2" zaxis="1 0 0" size="0.02 20" material="decoration" />
    

    <body name="cart" pos="0 0 2">
      <joint name="slider" type="slide" limited="true" axis="1 0 0" range="-999.8 999.8" damping="1e-3"/>
      <geom name="cart" type="box" size="0.1 0.15 0.05" material="self"  mass="1"/>
      <body name="pole_1" childclass="pole" euler="0 180 0" pos="0 0 -0.1">
        <joint name="hinge_1"/>
        <geom name="pole_1"/>
        <body name="pole_2" childclass="pole" pos="0 0 1.1">
          <joint name="hinge_2"/>
          <geom name="pole_2"/>
          <body name="segment_end" pos="0 0 1.0"/>
      	</body>
      </body>
    </body>
  </worldbody>

  <actuator>
    <motor name="slide" joint="slider" gear="5" ctrllimited="false"/>
  </actuator>
  
</mujoco>
